<?xml version="1.0" ?>
<robot name="mini" xmlns:xacro="http://www.ros.org/wiki/xacro">

<xacro:include filename="$(find mini_description)/urdf/materials.xacro" />
<xacro:include filename="$(find mini_description)/urdf/mini.trans" />
<xacro:include filename="$(find mini_description)/urdf/mini.gazebo" />
<link name="base_footprint"/>
<link name="base_link">
  <inertial>
    <origin xyz="0.007287773389227806 2.871730018162473e-18 0.0213343856882479" rpy="0 0 0"/>
    <mass value="0.7769198971267939"/>
    <inertia ixx="0.000207" iyy="0.000474" izz="0.00056" ixy="0.0" iyz="0.0" ixz="-4.8e-05"/>
  </inertial>
  <visual>
    <origin xyz="0 0 0" rpy="0 0 0"/>
    <geometry>
      <mesh filename="file://$(find mini_description)/meshes/base_link.stl" scale="0.001 0.001 0.001"/>
    </geometry>
    <material name="silver"/>
  </visual>
  <collision>
    <origin xyz="0 0 0" rpy="0 0 0"/>
    <geometry>
      <mesh filename="file://$(find mini_description)/meshes/base_link.stl" scale="0.001 0.001 0.001"/>
    </geometry>
  </collision>
</link>

<link name="wheel_c_1">
  <inertial>
    <origin xyz="2.5236113164461837e-08 4.440892098500626e-18 0.004297073089163117" rpy="0 0 0"/>
    <mass value="0.002723133997601544"/>
    <inertia ixx="0.0" iyy="0.0" izz="0.0" ixy="-0.0" iyz="0.0" ixz="-0.0"/>
  </inertial>
  <visual>
    <origin xyz="0.046999 -0.0 -0.0" rpy="0 0 0"/>
    <geometry>
      <mesh filename="file://$(find mini_description)/meshes/wheel_c_1.stl" scale="0.001 0.001 0.001"/>
    </geometry>
    <material name="silver"/>
  </visual>
  <collision>
    <origin xyz="0.046999 -0.0 -0.0" rpy="0 0 0"/>
    <geometry>
      <mesh filename="file://$(find mini_description)/meshes/wheel_c_1.stl" scale="0.001 0.001 0.001"/>
    </geometry>
  </collision>
</link>

<link name="wheel_l_1">
  <inertial>
    <origin xyz="-2.4118535290468257e-08 -0.0037869999999999952 1.490116086078075e-10" rpy="0 0 0"/>
    <mass value="0.024048526174821783"/>
    <inertia ixx="2e-06" iyy="4e-06" izz="2e-06" ixy="0.0" iyz="-0.0" ixz="-0.0"/>
  </inertial>
  <visual>
    <origin xyz="-0.021999 0.025 -0.018" rpy="0 0 0"/>
    <geometry>
      <mesh filename="file://$(find mini_description)/meshes/wheel_l_1.stl" scale="0.001 0.001 0.001"/>
    </geometry>
    <material name="silver"/>
  </visual>
  <collision>
    <origin xyz="-0.021999 0.025 -0.018" rpy="0 0 0"/>
    <geometry>
      <mesh filename="file://$(find mini_description)/meshes/wheel_l_1.stl" scale="0.001 0.001 0.001"/>
    </geometry>
  </collision>
</link>

<link name="wheel_r_1">
  <inertial>
    <origin xyz="-2.4118535290468257e-08 0.003787000000000002 1.490116086078075e-10" rpy="0 0 0"/>
    <mass value="0.024048526174821783"/>
    <inertia ixx="2e-06" iyy="4e-06" izz="2e-06" ixy="0.0" iyz="0.0" ixz="-0.0"/>
  </inertial>
  <visual>
    <origin xyz="-0.021999 -0.025 -0.018" rpy="0 0 0"/>
    <geometry>
      <mesh filename="file://$(find mini_description)/meshes/wheel_r_1.stl" scale="0.001 0.001 0.001"/>
    </geometry>
    <material name="silver"/>
  </visual>
  <collision>
    <origin xyz="-0.021999 -0.025 -0.018" rpy="0 0 0"/>
    <geometry>
      <mesh filename="file://$(find mini_description)/meshes/wheel_r_1.stl" scale="0.001 0.001 0.001"/>
    </geometry>
  </collision>
</link>

<joint name="base_joint" type="fixed">
  <parent link="base_footprint"/>
  <child link="base_link"/>
  <origin rpy="0 0 0" xyz="0 0 0.005"/>
</joint>
    
<joint name="Revolute 3" type="continuous">
  <origin xyz="-0.046999 0.0 0.0" rpy="0 0 0"/>
  <parent link="base_link"/>
  <child link="wheel_c_1"/>
  <axis xyz="0.0 0.0 -1.0"/>
</joint>

<joint name="Revolute 6" type="continuous">
  <origin xyz="0.021999 -0.025 0.018" rpy="0 0 0"/>
  <parent link="base_link"/>
  <child link="wheel_l_1"/>
  <axis xyz="0.0 -1.0 0.0"/>
</joint>

<joint name="Revolute 7" type="continuous">
  <origin xyz="0.021999 0.025 0.018" rpy="0 0 0"/>
  <parent link="base_link"/>
  <child link="wheel_r_1"/>
  <axis xyz="0.0 -1.0 0.0"/>
</joint>

</robot>
